Workbook
Name _: #REF!
Name 논공휴게소: #REF!
Name 식약처수거검사일지: #REF!
Name ㅇㅇ: #REF!
Name 운영: #REF!
Name 운영미흡: #REF!
Name 운영보통: #REF!
Name 운영양호: #REF!
Name 운영칸: #REF!
Name 위생: #REF!
Name 위생칸: #REF!
Name 위운영점수: #REF!
Name 일지: #REF!
Name 직운영점수: #REF!
Name 직운영칸: #REF!
Name 푸드트럭: #REF!

Sheet 26-4월4주차
B1: 주간 메뉴표(06.29 ~ 07.03)
B4: 구분 | F4: 46202 | G4: =F4+1 | H4: =G4+1 | I4: =H4+1 | J4: =I4+1
B5: 조식 | D5: 코너2 (한식) | E5: 메인 | F5: 소고기장조림 | G5: 임연수구이 | H5: 두부계란조림 | I5: 삼치양념구이 | J5: 훈제오리볶음
E6: 사이드 | F6: 잡곡밥/숭늉 | G6: 잡곡밥/숭늉 | H6: 잡곡밥/숭늉 | I6: 잡곡밥/숭늉 | J6: 잡곡밥/숭늉
F7: 얼갈이된장국 | G7: 버섯맑은국 | H7: 시원한뭇국 | I7: 아욱국 | J7: 시래기해장국
F8: 도라지나물 | G8: 가지볶음 | H8: 브로콜리무침 | I8: 세발나물무침 | J8: 곤드레나물
F9: 총각김치 | G9: 열무김치 | H9: 나박김치 | I9: 오이소박이 | J9: 석박지
D10: 코너3 (스낵) | E10: 메인 | F10: 유부초밥 | G10: 소고기김밥 | H10: 참치마요주먹밥 | I10: 멸치견과김밥 | J10: 매콤어묵김밥
E11: 사이드 | F11: 바지락맑은장국 | G11: 김치장국 | H11: 가쓰오장국 | I11: 북어채장국 | J11: 매생이장국
F12: 쌈무 | G12: 우엉조림 | H12: 오이초무침 | I12: 연근조림 | J12: 무피클 | N12: 차돌박이양배추메밀면
F13: 딸기주스 | G13: 바나나우유 | H13: 토마토주스 | I13: 초코우유 | J13: 자몽주스 | N13: 김치삼겹컵밥
D15: 셀프라면 ZON (Café) | F15: 셀프라면/쌀밥/배추김치 | G15: 셀프라면/토핑4종/배추김치 | H15: 셀프라면/토핑4종/배추김치 | I15: 셀프라면/토핑4종/배추김치 | J15: 셀프라면/쌀밥/배추김치 | N15: 돼지국밥 | S15: 시금치알리오올리오
F16: 토핑4종(계란,파,치즈,콩나물) | G16: 토핑4종(계란,파,치즈,비엔나) | H16: 토핑4종(계란,파,치즈,청양고추) | I16: 토핑4종(계란,파,치즈,떡국떡) | J16: 토핑4종(계란,파,치즈,양파) | S16: 아보카도명란밥
F17: 고객만족도조사 | G17: 애정메뉴 모음ZIP | H17: 오늘은 뭘 먹지? | I17: 맛ZIP탐방 | J17: 금요 행복밥상 | S17: 명란오일파스타
B18: 중식 | D18: 코너1 (일품) | E18: 메인 | F18: 사골소고기국수 | G18: 바지락칼국수 | H18: 새우로제파스타 | I18: 열무비빔국수 | J18: 삼선짬뽕 | N18: 차돌된장크림파스타 | S18: 명란크림우동
E19: 사이드 | F19: 꼬마주먹밥 | G19: 단호박죽 | H19: 마늘바게트 | I19: 미니유부초밥 | J19: 꽃빵 | N19: 고구마무스타코야끼 | S19: 짚신돼지갈비찜
F20: 야채튀김 | G20: 고구마튀김 | H20: 크래미튀김 | I20: 오징어링튀김 | J20: 김말이튀김 | N20: 도토리묵사발 | S20: 남산돈까스
F21: 코울슬로 | G21: 방울토마토 | H21: 감자샐러드 | I21: 톳두부무침 | J21: 리코타샐러드 | N21: 목살스테이크 | S21: 차돌애호박파스타
F22: 고들빼기김치 | G22: 부추김치 | H22: 깻잎김치 | I22: 동치미 | J22: 얼갈이김치 | N22: 나가사끼짬뽕 | S22: 분짜
D23: 코너2 (한식) | E23: 메인 | F23: 돼지고기김치찜 | G23: 갈치조림 | H23: 낙지볶음 | I23: 닭볶음탕 | J23: 동태매운탕 | N23: 봄동비빔국수 | S23: 바람의핫도그
E24: 사이드 | F24: 잡곡밥 | G24: 수수밥 | H24: 잡곡밥 | I24: 흑미밥 | J24: 잡곡밥 | N24: 태국식제육볶음 | S24: 삼겹살김치덮밥
F25: 시금치된장국 | G25: 두부새우젓국 | H25: 아욱국 | I25: 달래된장국 | J25: 배추된장국 | N25: 전복내장솥밥 | S25: 갓돈김치찌개
F26: 느타리버섯전 | G26: 뿌리채소조림 | H26: 콘치즈 | I26: 감자채볶음 | J26: 애호박전 | N26: 쭈꾸미볶음 | S26: 후추볶음밥(페퍼런치)
F27: 무나물 | G27: 미역줄기볶음 | H27: 참나물무침 | I27: 얼갈이나물 | J27: 도라지생채 | N27: 왕새우또띠아 | S27: 마라마파두부
F28: 총각김치 | G28: 오이소박이 | H28: 나박김치 | I28: 석박지 | J28: 열무김치 | N28: 새우튀김카레우동 | S28: 참깨수제비
D29: 코너3 (별식) | E29: SET구성 | F29: 곤드레밥&강된장 | G29: 낙지비빔밥 | H29: 불고기덮밥 | I29: 오므라이스 | J29: 치킨마요덮밥 | N29: 어향가지덮밥
F30: 유부어묵국 | G30: 콩나물황태국 | H30: 시원한버섯국 | I30: 옥수수크림스프 | J30: 계란파국 | N30: 비벼먹는된장찌개 | S30: 제주음식탐방
F31: 김말이강정 | G31: 치즈스틱 | H31: 고구마맛탕 | I31: 새우까스 | J31: 감자크로켓 | N31: 흑임자제육비빔밥 | S31: 고기국수/고사리육개장/
F32: 들깨코울슬로 | G32: 야채스틱&소스 | H32: 방울토마토 | I32: 포테이토샐러드 | J32: 브로콜리무침 | N32: 규동
F33: 열무김치 | G33: 석박지 | H33: 총각김치 | I33: 부추김치 | J33: 오이소박이 | S33: 레몬크림탕수육
D34: 플러스바 | F34: 그린샐러드/드레싱2종 | G34: 그린샐러드/드레싱2종 | H34: 그린샐러드/드레싱2종 | I34: 그린샐러드/드레싱2종 | J34: 그린샐러드/드레싱2종 | S34: 마제소바
F35: 현미밥/청포도에이드 | G35: 현미밥/수정과 | H35: 현미밥/옥수수차 | I35: 현미밥/오미자차 | J35: 현미밥/식혜 | N35: 파김치참치비빔밥
D36: 테이크아웃 (Café) | E36: 메인 | F36: 로스트치킨샐러드 | G36: 리코타치즈샐러드 | H36: 멕시칸비프샐러드 | I36: 통새우시저샐러드 | J36: 발사믹훈제오리샐러드
B37: 석식 | D37: 코너2 (한식&일품) | E37: 메인 | F37: LA갈비구이 | G37: 해물뚝배기 | H37: 마파두부덮밥 | I37: 코다리강정 | J37: 뼈없는감자탕
E38: 사이드 | F38: 잡곡밥 | G38: 잡곡밥 | H38: 미니잔치국수 | I38: 흑미밥 | J38: 잡곡밥
F39: 시래기국 | G39: 달걀파국 | H39: 가쓰오맑은국 | I39: 청국장찌개 | J39: 얼큰콩나물국
F40: 버섯잡채 | G40: 새우완자전 | H40: 야채춘권튀김 | I40: 단호박맛탕 | J40: 부추전
F41: 가지나물 | G41: 우엉조림 | H41: 무생채 | I41: 참나물겉절이 | J41: 시금치나물
F42: 나박김치 | G42: 오이소박이 | H42: 석박지 | I42: 고들빼기김치 | J42: 총각김치
D43: 셀프라면 ZON (Café) | F43: 셀프라면/쌀밥/배추김치 | G43: 셀프라면/토핑4종/배추김치 | H43: 셀프라면/토핑4종/배추김치 | I43: 셀프라면/토핑4종/배추김치 | J43: 셀프라면/토핑4종/배추김치
...

Sheet 보존식
A1: 보존식 기록표 (조식) | E1: 보존식 기록표 (조식) | I1: 보존식 기록표 (조식) | M1: 보존식 기록표 (조식) | Q1: 보존식 기록표 (조식)
A2: 식단명 월 코너2 | B2: ='26-4월4주차'!F5 | E2: 식단명 화 코너2 | F2: ='26-4월4주차'!#REF! | I2: 식단명 수 코너2 | J2: ='26-4월4주차'!#REF! | M2: 식단명 목 코너2 | N2: ='26-4월4주차'!I5 | Q2: 식단명 금 코너2 | R2: ='26-4월4주차'!J5
B3: ='26-4월4주차'!F6 | F3: ='26-4월4주차'!G5 | J3: ='26-4월4주차'!H6 | N3: ='26-4월4주차'!I6 | R3: ='26-4월4주차'!J6
B4: ='26-4월4주차'!F7 | F4: ='26-4월4주차'!G7 | J4: ='26-4월4주차'!H7 | N4: ='26-4월4주차'!I7 | R4: ='26-4월4주차'!J7
B5: ='26-4월4주차'!F8 | F5: ='26-4월4주차'!G8 | J5: ='26-4월4주차'!H8 | N5: ='26-4월4주차'!I8 | R5: ='26-4월4주차'!J8
B6: ='26-4월4주차'!F9 | F6: ='26-4월4주차'!G9 | J6: ='26-4월4주차'!H9 | N6: ='26-4월4주차'!I9 | R6: ='26-4월4주차'!J9
A7: 식당 | B7: NH농협타워점 | E7: 식당 | F7: NH농협타워점 | I7: 식당 | J7: NH농협타워점 | M7: 식당 | N7: NH농협타워점 | Q7: 식당 | R7: NH농협타워점
A8: 관리리준 | B8: 관리기준 : 1.고객에게 제공한 모든 식품은 1인 분량(150g 이상) 전용 스텐용기나 멸균팩에 담아 -18℃이하 냉동고에서 144시간 이상 보관한다. 2.보존식 제외 품목의 경우, 별도 확인·추적할 수 있는 정보를 관리일지에 작성 및 보관한다. | E8: 관리리준 | F8: 관리기준 : 1.고객에게 제공한 모든 식품은 1인 분량(150g 이상) 전용 스텐용기나 멸균팩에 담아 -18℃이하 냉동고에서 144시간 이상 보관한다. 2.보존식 제외 품목의 경우, 별도 확인·추적할 수 있는 정보를 관리일지에 작성 및 보관한다. | I8: 관리리준 | J8: 관리기준 : 1.고객에게 제공한 모든 식품은 1인 분량(150g 이상) 전용 스텐용기나 멸균팩에 담아 -18℃이하 냉동고에서 144시간 이상 보관한다. 2.보존식 제외 품목의 경우, 별도 확인·추적할 수 있는 정보를 관리일지에 작성 및 보관한다. | M8: 관리리준 | N8: 관리기준 : 1.고객에게 제공한 모든 식품은 1인 분량(150g 이상) 전용 스텐용기나 멸균팩에 담아 -18℃이하 냉동고에서 144시간 이상 보관한다. 2.보존식 제외 품목의 경우, 별도 확인·추적할 수 있는 정보를 관리일지에 작성 및 보관한다. | Q8: 관리리준 | R8: 관리기준 : 1.고객에게 제공한 모든 식품은 1인 분량(150g 이상) 전용 스텐용기나 멸균팩에 담아 -18℃이하 냉동고에서 144시간 이상 보관한다. 2.보존식 제외 품목의 경우, 별도 확인·추적할 수 있는 정보를 관리일지에 작성 및 보관한다.
A9: 채취일 | B9: ='26-4월4주차'!F4 | D9: 0.3125 | E9: 채취일 | F9: =B9+1 | H9: 0.3125 | I9: 채취일 | J9: =F9+1 | L9: 0.3125 | M9: 채취일 | N9: =J9+1 | P9: 0.3125 | Q9: 채취일 | R9: =N9+1 | T9: 0.3125
A10: 폐기일 | B10: =B9+6 | D10: 0.3125 | E10: 폐기일 | F10: =F9+6 | H10: 0.3125 | I10: 폐기일 | J10: =J9+6 | L10: 0.3125 | M10: 폐기일 | N10: =N9+6 | P10: 0.3125 | Q10: 폐기일 | R10: =R9+6 | T10: 0.3125
A11: 채취자 | E11: 채취자 | I11: 채취자 | M11: 채취자 | Q11: 채취자
A12: 보존식 기록표 (조식) | E12: 보존식 기록표 (조식) | I12: 보존식 기록표 (조식) | M12: 보존식 기록표 (조식) | Q12: 보존식 기록표 (조식)
A13: 식단명 월 코너3 | B13: ='26-4월4주차'!F10 | E13: 식단명 화 코너3 | F13: ='26-4월4주차'!G10 | I13: 식단명 수 코너3 | J13: ='26-4월4주차'!H10 | M13: 식단명 목 코너3 | N13: ='26-4월4주차'!I10 | Q13: 식단명 금 코너3 | R13: ='26-4월4주차'!J10
B14: ='26-4월4주차'!F11 | F14: ='26-4월4주차'!G11 | J14: ='26-4월4주차'!H11 | N14: ='26-4월4주차'!I11 | R14: ='26-4월4주차'!J11
B15: ='26-4월4주차'!F12 | F15: ='26-4월4주차'!G12 | J15: ='26-4월4주차'!H12 | N15: ='26-4월4주차'!I12 | R15: ='26-4월4주차'!J12
B16: ='26-4월4주차'!F13 | F16: ='26-4월4주차'!G13 | J16: ='26-4월4주차'!H13 | N16: ='26-4월4주차'!I13 | R16: ='26-4월4주차'!J13
A17: 식당 | B17: NH농협타워점 | E17: 식당 | F17: NH농협타워점 | I17: 식당 | J17: NH농협타워점 | M17: 식당 | N17: NH농협타워점 | Q17: 식당 | R17: NH농협타워점
A18: 관리리준 | B18: 관리기준 : 1.고객에게 제공한 모든 식품은 1인 분량(150g 이상) 전용 스텐용기나 멸균팩에 담아 -18℃이하 냉동고에서 144시간 이상 보관한다. 2.보존식 제외 품목의 경우, 별도 확인·추적할 수 있는 정보를 관리일지에 작성 및 보관한다. | E18: 관리리준 | F18: 관리기준 : 1.고객에게 제공한 모든 식품은 1인 분량(150g 이상) 전용 스텐용기나 멸균팩에 담아 -18℃이하 냉동고에서 144시간 이상 보관한다. 2.보존식 제외 품목의 경우, 별도 확인·추적할 수 있는 정보를 관리일지에 작성 및 보관한다. | I18: 관리리준 | J18: 관리기준 : 1.고객에게 제공한 모든 식품은 1인 분량(150g 이상) 전용 스텐용기나 멸균팩에 담아 -18℃이하 냉동고에서 144시간 이상 보관한다. 2.보존식 제외 품목의 경우, 별도 확인·추적할 수 있는 정보를 관리일지에 작성 및 보관한다. | M18: 관리리준 | N18: 관리기준 : 1.고객에게 제공한 모든 식품은 1인 분량(150g 이상) 전용 스텐용기나 멸균팩에 담아 -18℃이하 냉동고에서 144시간 이상 보관한다. 2.보존식 제외 품목의 경우, 별도 확인·추적할 수 있는 정보를 관리일지에 작성 및 보관한다. | Q18: 관리리준 | R18: 관리기준 : 1.고객에게 제공한 모든 식품은 1인 분량(150g 이상) 전용 스텐용기나 멸균팩에 담아 -18℃이하 냉동고에서 144시간 이상 보관한다. 2.보존식 제외 품목의 경우, 별도 확인·추적할 수 있는 정보를 관리일지에 작성 및 보관한다.
A19: 채취일 | B19: =B9 | D19: 0.3125 | E19: 채취일 | F19: =F9 | H19: 0.3125 | I19: 채취일 | J19: =J9 | L19: 0.3125 | M19: 채취일 | N19: =N9 | P19: 0.3125 | Q19: 채취일 | R19: =R9 | T19: 0.3125
A20: 폐기일 | B20: =B19+6 | D20: 0.3125 | E20: 폐기일 | F20: =F19+6 | H20: 0.3125 | I20: 폐기일 | J20: =J19+6 | L20: 0.3125 | M20: 폐기일 | N20: =N19+6 | P20: 0.3125 | Q20: 폐기일 | R20: =R19+6 | T20: 0.3125
A21: 채취자 | E21: 채취자 | I21: 채취자 | M21: 채취자 | Q21: 채취자
A22: 보존식 기록표 (조식) | E22: 보존식 기록표 (조식) | I22: 보존식 기록표 (조식) | M22: 보존식 기록표 (조식) | Q22: 보존식 기록표 (조식)
A23: 식단명 월 라면코너 | B23: 파/계란/치즈/콩나물 | E23: 식단명 화 라면코너 | F23: 파/계란/치즈/비엔나 | I23: 식단명 수 라면코너 | J23: 파/계란/치즈/청양고추 | M23: 식단명 목 라면코너 | N23: 파/계란/치즈/떡국떡 | Q23: 식단명 금 라면코너 | R23: 파/계란/치즈/양파
B24: 단무지 | F24: 단무지 | J24: 단무지 | N24: 단무지 | R24: 단무지
B25: 배추김치 | F25: 배추김치 | J25: 배추김치 | N25: 배추김치 | R25: 배추김치
B26: 쌀밥 | F26: 쌀밥 | J26: 쌀밥 | N26: 쌀밥 | R26: 쌀밥
A27: 식당 | B27: NH농협타워점 | E27: 식당 | F27: NH농협타워점 | I27: 식당 | J27: NH농협타워점 | M27: 식당 | N27: NH농협타워점 | Q27: 식당 | R27: NH농협타워점
A28: 관리리준 | B28: 관리기준 : 1.고객에게 제공한 모든 식품은 1인 분량(150g 이상) 전용 스텐용기나 멸균팩에 담아 -18℃이하 냉동고에서 144시간 이상 보관한다. 2.보존식 제외 품목의 경우, 별도 확인·추적할 수 있는 정보를 관리일지에 작성 및 보관한다. | E28: 관리리준 | F28: 관리기준 : 1.고객에게 제공한 모든 식품은 1인 분량(150g 이상) 전용 스텐용기나 멸균팩에 담아 -18℃이하 냉동고에서 144시간 이상 보관한다. 2.보존식 제외 품목의 경우, 별도 확인·추적할 수 있는 정보를 관리일지에 작성 및 보관한다. | I28: 관리리준 | J28: 관리기준 : 1.고객에게 제공한 모든 식품은 1인 분량(150g 이상) 전용 스텐용기나 멸균팩에 담아 -18℃이하 냉동고에서 144시간 이상 보관한다. 2.보존식 제외 품목의 경우, 별도 확인·추적할 수 있는 정보를 관리일지에 작성 및 보관한다. | M28: 관리리준 | N28: 관리기준 : 1.고객에게 제공한 모든 식품은 1인 분량(150g 이상) 전용 스텐용기나 멸균팩에 담아 -18℃이하 냉동고에서 144시간 이상 보관한다. 2.보존식 제외 품목의 경우, 별도 확인·추적할 수 있는 정보를 관리일지에 작성 및 보관한다. | Q28: 관리리준 | R28: 관리기준 : 1.고객에게 제공한 모든 식품은 1인 분량(150g 이상) 전용 스텐용기나 멸균팩에 담아 -18℃이하 냉동고에서 144시간 이상 보관한다. 2.보존식 제외 품목의 경우, 별도 확인·추적할 수 있는 정보를 관리일지에 작성 및 보관한다.
A29: 채취일 | B29: =B9 | D29: 0.3125 | E29: 채취일 | F29: =F9 | H29: 0.3125 | I29: 채취일 | J29: =J9 | L29: 0.3125 | M29: 채취일 | N29: =N9 | P29: 0.3125 | Q29: 채취일 | R29: =R9 | T29: 0.3125
A30: 폐기일 | B30: =B29+6 | D30: 0.3125 | E30: 폐기일 | F30: =F29+6 | H30: 0.3125 | I30: 폐기일 | J30: =J29+6 | L30: 0.3125 | M30: 폐기일 | N30: =N29+6 | P30: 0.3125 | Q30: 폐기일 | R30: =R29+6 | T30: 0.3125
A31: 채취자 | E31: 채취자 | I31: 채취자 | M31: 채취자 | Q31: 채취자
A32: 보존식 기록표 (중식) | E32: 보존식 기록표 (중식) | I32: 보존식 기록표 (중식) | M32: 보존식 기록표 (중식) | Q32: 보존식 기록표 (중식)
A33: 식단명 월 코너1 | B33: ='26-4월4주차'!F18 | E33: 식단명 화 코너1 | F33: ='26-4월4주차'!G18 | I33: 식단명 수 코너1 | J33: ='26-4월4주차'!H19 | M33: 식단명 목 코너1 | N33: ='26-4월4주차'!I18 | Q33: 식단명 금 코너1 | R33: 마늘보쌈
B34: ='26-4월4주차'!F19 | F34: ='26-4월4주차'!G19 | J34: ='26-4월4주차'!#REF! | N34: ='26-4월4주차'!I19 | R34: 잡곡밥
B35: ='26-4월4주차'!F20 | F35: ='26-4월4주차'!G20 | J35: ='26-4월4주차'!H20 | N35: ='26-4월4주차'!I20 | R35: 냉이된장국
B36: ='26-4월4주차'!F21 | F36: ='26-4월4주차'!#REF! | J36: ='26-4월4주차'!H21 | N36: ='26-4월4주차'!I21 | R36: 들기름막국수
B37: ='26-4월4주차'!#REF! | F37: ='26-4월4주차'!G21 | J37: ='26-4월4주차'!#REF! | N37: ='26-4월4주차'!#REF! | R37: 모듬쌈&쌈장
B38: ='26-4월4주차'!F22 | F38: ='26-4월4주차'!G22 | J38: ='26-4월4주차'!H22 | N38: ='26-4월4주차'!I22 | R38: 배추김치
A39: 식당 | B39: NH농협타워점 | E39: 식당 | F39: NH농협타워점 | I39: 식당 | J39: NH농협타워점 | M39: 식당 | N39: NH농협타워점 | Q39: 식당 | R39: NH농협타워점
A40: 관리리준 | B40: 관리기준 : 1.고객에게 제공한 모든 식품은 1인 분량(150g 이상) 전용 스텐용기나 멸균팩에 담아 -18℃이하 냉동고에서 144시간 이상 보관한다. 2.보존식 제외 품목의 경우, 별도 확인·추적할 수 있는 정보를 관리일지에 작성 및 보관한다. | E40: 관리리준 | F40: 관리기준 : 1.고객에게 제공한 모든 식품은 1인 분량(150g 이상) 전용 스텐용기나 멸균팩에 담아 -18℃이하 냉동고에서 144시간 이상 보관한다. 2.보존식 제외 품목의 경우, 별도 확인·추적할 수 있는 정보를 관리일지에 작성 및 보관한다. | I40: 관리리준 | J40: 관리기준 : 1.고객에게 제공한 모든 식품은 1인 분량(150g 이상) 전용 스텐용기나 멸균팩에 담아 -18℃이하 냉동고에서 144시간 이상 보관한다. 2.보존식 제외 품목의 경우, 별도 확인·추적할 수 있는 정보를 관리일지에 작성 및 보관한다. | M40: 관리리준 | N40: 관리기준 : 1.고객에게 제공한 모든 식품은 1인 분량(150g 이상) 전용 스텐용기나 멸균팩에 담아 -18℃이하 냉동고에서 144시간 이상 보관한다. 2.보존식 제외 품목의 경우, 별도 확인·추적할 수 있는 정보를 관리일지에 작성 및 보관한다. | Q40: 관리리준 | R40: 관리기준 : 1.고객에게 제공한 모든 식품은 1인 분량(150g 이상) 전용 스텐용기나 멸균팩에 담아 -18℃이하 냉동고에서 144시간 이상 보관한다. 2.보존식 제외 품목의 경우, 별도 확인·추적할 수 있는 정보를 관리일지에 작성 및 보관한다.
...
